Workbook

Sheet Overview
A1: BRITISH LAND PLC (BLND.L) — INVESTMENT ANALYSIS
A2: UK REIT | London Campuses, Retail Parks, Urban Logistics | FY ending 31 March
A4: KEY METRICS (FY25 Actuals)
A5: Portfolio Value (£bn) | B5: 9.5 | F5: Proportionally consolidated, inc. share of JVs
A6: EPRA NTA per share (p) | B6: 567 | F6: Source: AR2025 p.2
A7: Current Share Price (p) | B7: 388 | F7: As at 8 April 2026
A8: Discount to NTA | B8: -32% | F8: (388-567)/567
A9: Underlying EPS — diluted (p) | B9: 28.5 | F9: Flat vs FY24; share placing dilution offset profit growth
A10: Dividend per share (p) | B10: 22.80 | F10: 80% payout of Underlying EPS
A11: Dividend Yield | B11: 5.9% | F11: At 388p
A12: LTV (proportionally consolidated) | B12: 38.1% | F12: FY25; up from 37.3% in FY24
A13: Net Debt / EBITDA | B13: 8.0x | F13: Group basis; up from 6.8x in FY24
A14: Weighted Avg Interest Rate | B14: 3.6% | F14: 97% hedged for FY26; no refi needed until late 2028
A15: Occupancy — Campuses | B15: 97% | F15: Excl. developments; EPRA basis 83% (new space)
A16: Occupancy — Retail Parks | B16: 99% | F16: Virtually full
... A18: Credit Rating (Fitch) | B18: A (stable) | F18: Held since 2018
A20: DCF SCENARIO SUMMARY
B21: BEAR | C21: BASE | D21: BULL | F21: All figures from DCF Valuation sheet
A22: Earnings Growth Assumption | B22: ='DCF Valuation'!B6 -> 0.01 | C22: ='DCF Valuation'!C6 -> 0.03 | D22: ='DCF Valuation'!D6 -> 0.05
A23: Exit Multiple | B23: ='DCF Valuation'!B7 -> 0.065 | C23: ='DCF Valuation'!C7 -> 0.055 | D23: ='DCF Valuation'!D7 -> 0.05
A24: Implied Share Price (p) | B24: ='DCF Valuation'!B43 -> 257.20575 | C24: ='DCF Valuation'!C43 -> 406.0427 | D24: ='DCF Valuation'!D43 -> 542.39435
A25: Upside / (Downside) vs 388p | B25: ='DCF Valuation'!B45 -> -0.33709859 | C25: ='DCF Valuation'!C45 -> 0.046501797 | D25: ='DCF Valuation'!D45 -> 0.39792358
A26: vs EPRA NTA (567p) | B26: ='DCF Valuation'!B47 -> -0.54637435 | C26: ='DCF Valuation'!C47 -> -0.28387531 | D26: ='DCF Valuation'!D47 -> -0.043396208
A28: INVESTMENT THESIS SUMMARY
A29: • British Land is the UK's second-largest listed REIT, owning £9.5bn of London campuses, retail parks and urban logistics.
A30: • The stock trades at a ~32% discount to EPRA NTA (567p vs 388p), pricing in persistent office risk and balance sheet concerns.
A31: • Retail parks (32% of portfolio) are performing strongly: 99% occupancy, 6% ERV growth, virtually no supply.
A32: • Campus ERV growth of 4.3% and pre-letting pipeline (2 Finsbury Ave: Citadel pre-let) suggest office demand is real.
A33: • Key risk: office thesis remains contested. If WFH structural shift continues, campus values (58% of portfolio) face pressure.
A34: • Management guides FY26 EPS flat, then 3-6% annual growth. No refinancing required until late 2028. Dividend yield ~5.9%.

Sheet Assumptions
A1: ASSUMPTIONS — All blue cells are inputs. Change here; everything updates.
A3: SCENARIO ASSUMPTIONS
B4: BEAR | C4: BASE | D4: BULL | F4: Blue = input
A5: FY25 Underlying Profit — base (£m)
A6: Underlying Profit FY25 actual (£m) | B6: 279 | C6: 279 | D6: 279 | F6: Source: AR2025. No company adjustments in FY25 so = EPRA Earnings
A7: Shares outstanding — diluted (m) | B7: 965 | C7: 965 | D7: 965 | F7: FY25 weighted avg diluted; ~1,000m post Life Science REIT completion Apr 2026
A9: DCF Assumptions
A10: Annual EPRA Earnings growth — FY26-30 (%) | B10: 0.01 | C10: 0.03 | D10: 0.05 | F10: Bear: flat (office headwinds). Base: mgmt guidance 3-5%. Bull: full lease-up + reversion
A11: Exit multiple — Year 5 EPRA Earnings (x) | B11: 14 | C11: 17 | D11: 20 | F11: Historical range 15-20x. Bear: office discount. Bull: re-rating on improved sentiment
A12: Required return / discount rate (%) | B12: 0.1 | C12: 0.1 | D12: 0.1 | F12: 10% — consistent with prior analyses in this series
A14: Balance Sheet
A15: Net debt — proportionally consolidated (£m) | B15: 3637 | C15: 3637 | D15: 3637 | F15: Source: AR2025 balance sheet. Adjusted net debt inc. share of JV debt
A16: EPRA NTA per share (pence) | B16: 567 | C16: 567 | D16: 567 | F16: Source: AR2025 p.2
A17: Current share price (pence) | B17: 388 | C17: 388 | D17: 388 | F17: As at 8 April 2026
A19: Portfolio Assumptions (for NAV cross-check)
A20: Portfolio value — proportionally consol. (£m) | B20: 9489 | C20: 9489 | D20: 9489 | F20: Source: AR2025. Includes share of JVs
A21: Other net liabilities / assets (£m) | B21: -218 | C21: -218 | D21: -218 | F21: Other net current liabilities per balance sheet

Sheet Portfolio
A1: BRITISH LAND — PORTFOLIO BREAKDOWN (as at 31 March 2025)
A3: SEGMENT OVERVIEW
A4: Segment | B4: Value (£m) | C4: % of Portfolio | D4: Occupancy | E4: ERV Growth | F4: Like-for-like NRI Growth | G4: Notes
A5: Campuses (total) | B5: 5501 | C5: 0.57972389 | D5: 0.965 | E5: 0.043 | F5: 0.02 | G5: Broadgate, Regent's Place, Paddington, Canada Water
A6: Retail Parks | B6: 2800 | C6: 0.29507851 | D6: 0.99 | E6: 0.06 | F6: 0.05 | G6: Acquired £738m of parks in FY25; 99% occupancy
A7: Shopping Centres | B7: 540 | C7: 0.056907999 | D7: 0.98 | E7: 0.021 | F7: 0.04 | G7: Reducing exposure; sold Meadowhall 50% stake (£360m)
A8: London Urban Log. | B8: 145 | C8: 0.015280852 | E8: -0.049 | G8: Early-stage; 1.2m sq ft pipeline; first scheme in Southwark
A9: Other / Canada W. | B9: 503 | C9: 0.053008747 | G9: Mixed-use development; offices, retail, residential, community
A10: TOTAL PORTFOLIO | B10: 9489 | C10: 1
A12: KEY CAMPUS ASSETS
A13: Asset | B13: Location | C13: Value (£m) | D13: Occupancy | E13: ERV Growth (FY25) | F13: Key Tenants / Activity
A14: Broadgate | B14: City of London | C14: 2400 | D14: 0.97 | E14: 0.073 | F14: Citadel (261k sq ft pre-let), Akin, A&O Shearman, Marex
A15: Regent's Place | B15: Fitzrovia / Euston | C15: 1500 | D15: 0.97 | E15: 0.031 | F15: AI & science hub; Synthesia, 7 AI occupiers; UCL/Crick proximity
A16: Paddington Central | B16: Paddington | C16: 850 | D16: 0.97 | E16: 0.031 | F16: 4 & 5 Kingdom Street; 142k sq ft of deals signed FY25
A17: Canada Water | B17: SE London | C17: 500 | F17: Long-term 53-acre mixed-use masterplan; early-stage residential/office
A18: Norton Folgate | B18: Shoreditch | C18: 251 | F18: Recently completed development; leasing underway
A20: PORTFOLIO HISTORY (Proportionally Consolidated, £m)
A21: Metric | B21: FY22 | C21: FY23 | D21: FY24 | E21: FY25
A22: Portfolio Valuation (£m) | B22: 10647 | C22: 8895 | D22: 8685 | E22: 9489
A23: Occupancy (%) | B23: 0.965 | C23: 0.967 | D23: 0.972 | E23: 0.977
A24: Avg Lease Length (yrs) | B24: 5.8 | C24: 5.7 | D24: 5.2 | E24: 5.3
A25: Total Property Return (%) | B25: -0.0042 | C25: 0.0071 | D25: 0.02 | E25: 0.069
A26: Net Rental Income (£m) | D26: 440 | E26: 439
A27: Underlying EPS (p) | D27: 28.5 | E27: 28.5
A28: EPRA NTA per share (p) | D28: 562 | E28: 567
A29: LTV (%) | D29: 0.373 | E29: 0.381

Sheet DCF Valuation
A1: DCF VALUATION — Net Rental Income basis | Cap rate exit | 10% discount rate
B3: BEAR | C3: BASE | D3: BULL | F3: Blue = inputs you can change
A4: 1. ASSUMPTIONS
A5: FY25 Net Rental Income — actual (£m) | B5: 439 | C5: 439 | D5: 439 | F5: Source: AR2025. Starting point for all NRI forecasts
A6: Annual NRI growth rate — FY26-30 (%) | B6: 0.01 | C6: 0.03 | D6: 0.05 | F6: Bear: 1% (office leasing stalls). Base: 3% (mgmt guidance). Bull: 5% (full lease-up + reversion)
A7: Exit cap rate — applied to Year 5 NRI (%) | B7: 0.065 | C7: 0.055 | D7: 0.05 | F7: Bear: yield expansion (office risk). Base: ~current market. Bull: yield compression as sentiment improves
A8: Required return / discount rate (%) | B8: 0.1 | C8: 0.1 | D8: 0.1 | F8: 10% — consistent with prior analyses in this series
A9: Net debt — proportionally consolidated (£m) | B9: 3637 | C9: 3637 | D9: 3637 | F9: Source: AR2025 balance sheet
A10: Shares outstanding — diluted (m) | B10: 965 | C10: 965 | D10: 965 | F10: FY25 weighted avg diluted; approx 1,000m post Life Science REIT deal Apr 2026
A11: Current share price (pence) | B11: 388 | C11: 388 | D11: 388 | F11: As at 8 April 2026
A12: EPRA NTA per share (pence) | B12: 567 | C12: 567 | D12: 567 | F12: Source: AR2025 p.2
A14: 2. NET RENTAL INCOME FORECAST (£m)
B15: NRI (£m) | C15: NRI (£m) | D15: NRI (£m)
A16: FY26E | B16: =B5*(1+B6) -> 443.39 | C16: =C5*(1+C6) -> 452.17 | D16: =D5*(1+D6) -> 460.95
A17: FY27E | B17: =B16*(1+B6) -> 447.8239 | C17: =C16*(1+C6) -> 465.7351 | D17: =D16*(1+D6) -> 483.9975
A18: FY28E | B18: =B17*(1+B6) -> 452.30214 | C18: =C17*(1+C6) -> 479.70715 | D18: =D17*(1+D6) -> 508.19738
A19: FY29E | B19: =B18*(1+B6) -> 456.82516 | C19: =C18*(1+C6) -> 494.09837 | D19: =D18*(1+D6) -> 533.60724
A20: FY30E | B20: =B19*(1+B6) -> 461.39341 | C20: =C19*(1+C6) -> 508.92132 | D20: =D19*(1+D6) -> 560.28761
A22: 3. PRESENT VALUE OF NRI (£m)
B23: PV of NRI (£m) | C23: PV of NRI (£m) | D23: PV of NRI (£m)
A24: PV of FY26E [÷ (1+r)^1] | B24: =B16/(1+B8)^1 -> 403.08182 | C24: =C16/(1+C8)^1 -> 411.06364 | D24: =D16/(1+D8)^1 -> 419.04545
A25: PV of FY27E [÷ (1+r)^2] | B25: =B17/(1+B8)^2 -> 370.1024 | C25: =C17/(1+C8)^2 -> 384.90504 | D25: =D17/(1+D8)^2 -> 399.99793
A26: PV of FY28E [÷ (1+r)^3] | B26: =B18/(1+B8)^3 -> 339.82129 | C26: =C18/(1+C8)^3 -> 360.41108 | D26: =D18/(1+D8)^3 -> 381.81621
A27: PV of FY29E [÷ (1+r)^4] | B27: =B19/(1+B8)^4 -> 312.01773 | C27: =C19/(1+C8)^4 -> 337.47583 | D27: =D19/(1+D8)^4 -> 364.46093
A28: PV of FY30E [÷ (1+r)^5] | B28: =B20/(1+B8)^5 -> 286.48901 | C28: =C20/(1+C8)^5 -> 316.0001 | D28: =D20/(1+D8)^5 -> 347.89452
A29: Sum of PV of NRI (Years 1-5) | B29: =SUM(B24:B28) -> 1711.5122 | C29: =SUM(C24:C28) -> 1809.8557 | D29: =SUM(D24:D28) -> 1913.215 | F29: Income collected over 5 years, in today's money
A31: 4. EXIT VALUE (portfolio value at end of Year 5)
A32: Year 5 NRI (£m) | B32: =B20 -> 461.39341 | C32: =C20 -> 508.92132 | D32: =D20 -> 560.28761
A33: Exit portfolio value [Year 5 NRI ÷ cap rate] | B33: =B32/B7 -> 7098.3602 | C33: =C32/C7 -> 9253.1149 | D33: =D32/D7 -> 11205.752 | F33: Cap rate = NOI / property value. Rearranged: value = NOI / cap rate
A34: PV of exit portfolio value [÷ (1+r)^5] | B34: =B33/(1+B8)^5 -> 4407.5232 | C34: =C33/(1+C8)^5 -> 5745.4563 | D34: =D33/(1+D8)^5 -> 6957.8904
A36: 5. FROM PROPERTY VALUE TO SHARE PRICE
A37: Sum of PV of NRI (Years 1-5) | B37: =B29 -> 1711.5122 | C37: =C29 -> 1809.8557 | D37: =D29 -> 1913.215
A38: PV of exit portfolio value | B38: =B34 -> 4407.5232 | C38: =C34 -> 5745.4563 | D38: =D34 -> 6957.8904
A39: Total Property Value (EV) | B39: =B37+B38 -> 6119.0354 | C39: =C37+C38 -> 7555.312 | D39: =D37+D38 -> 8871.1055 | F39: What the property portfolio is worth today, based on these assumptions
A40: Less: net debt (£m) | B40: =-B9 -> -3637 | C40: =-C9 -> -3637 | D40: =-D9 -> -3637
A41: Equity Value (£m) | B41: =B39+B40 -> 2482.0354 | C41: =C39+C40 -> 3918.312 | D41: =D39+D40 -> 5234.1055
A42: Shares outstanding (m) | B42: =B10 -> 965 | C42: =C10 -> 965 | D42: =D10 -> 965
A43: Implied Share Price (pence) | B43: =B41/B10*100 -> 257.20575 | C43: =C41/C10*100 -> 406.0427 | D43: =D41/D10*100 -> 542.39435 | F43: ← Key output. Compare to current price (388p) and NTA (567p)
A44: Current share price (pence) | B44: =B11 -> 388 | C44: =C11 -> 388 | D44: =D11 -> 388
A45: Upside / (Downside) to current price (388p) | B45: =(B43-B44)/B44 -> -0.33709859 | C45: =(C43-C44)/C44 -> 0.046501797 | D45: =(D43-D44)/D44 -> 0.39792358
...

Sheet Charts
A1: CHARTS — Data for visualisation (for articles / presentations)
A3: Portfolio Valuation (£bn)
A4: Year | B4: Value (£m)
A5: FY22 | B5: 10647
A6: FY23 | B6: 8895
A7: FY24 | B7: 8685
A8: FY25 | B8: 9489
A10: NTA vs Share Price (pence)
A11: Year | B11: EPRA NTA | C11: Share Price
A12: FY24 | B12: 562 | C12: 410
A13: FY25 | B13: 567 | C13: 420
A14: Apr-26 | B14: 567 | C14: 388
A16: Portfolio Segment Mix (£m)
A17: Segment | B17: Value (£m)
A18: Campuses | B18: 5501
A19: Retail Parks | B19: 2800
A20: Shopping Centres | B20: 540
A21: Urban Logistics | B21: 145
A22: Other | B22: 503
